2025-03-24 15:12:19,200 INFO    StreamThr :2523557 [internal.py:wandb_internal():86] W&B internal server running at pid: 2523557, started at: 2025-03-24 15:12:19.198962
2025-03-24 15:12:19,202 DEBUG   HandlerThread:2523557 [handler.py:handle_request():144] handle_request: status
2025-03-24 15:12:19,207 INFO    WriterThread:2523557 [datastore.py:open_for_write():85] open: /scratch/bhanu/cuffless_bp/Cuffless_BP_Estimation_Diffusion_Model/wandb/run-20250324_151219-INSERT ID HERE/run-INSERT ID HERE.wandb
2025-03-24 15:12:19,208 DEBUG   SenderThread:2523557 [sender.py:send():379] send: header
2025-03-24 15:12:19,238 DEBUG   SenderThread:2523557 [sender.py:send():379] send: run
2025-03-24 15:12:19,836 ERROR   SenderThread:2523557 [internal_api.py:execute():361] 404 response executing GraphQL.
2025-03-24 15:12:19,836 ERROR   SenderThread:2523557 [internal_api.py:execute():362] {"errors":[{"message":"entity INSERT ENTITY HERE not found during upsertBucket","path":["upsertBucket"]}],"data":{"upsertBucket":null}}
2025-03-24 15:12:19,836 ERROR   SenderThread:2523557 [sender.py:send_run():976] It appears that you do not have permission to access the requested resource. Please reach out to the project owner to grant you access. If you have the correct permissions, verify that there are no issues with your networking setup.(Error 404: Not Found)
Traceback (most recent call last):
  File "/home/bhanu/cuffless_bp/diffusion/lib64/python3.8/site-packages/wandb/sdk/lib/retry.py", line 131, in __call__
    result = self._call_fn(*args, **kwargs)
  File "/home/bhanu/cuffless_bp/diffusion/lib64/python3.8/site-packages/wandb/sdk/internal/internal_api.py", line 358, in execute
    return self.client.execute(*args, **kwargs)  # type: ignore
  File "/home/bhanu/cuffless_bp/diffusion/lib64/python3.8/site-packages/wandb/vendor/gql-0.2.0/wandb_gql/client.py", line 52, in execute
    result = self._get_result(document, *args, **kwargs)
  File "/home/bhanu/cuffless_bp/diffusion/lib64/python3.8/site-packages/wandb/vendor/gql-0.2.0/wandb_gql/client.py", line 60, in _get_result
    return self.transport.execute(document, *args, **kwargs)
  File "/home/bhanu/cuffless_bp/diffusion/lib64/python3.8/site-packages/wandb/sdk/lib/gql_request.py", line 56, in execute
    request.raise_for_status()
  File "/home/bhanu/cuffless_bp/diffusion/lib64/python3.8/site-packages/requests/models.py", line 1021, in raise_for_status
    raise HTTPError(http_error_msg, response=self)
requests.exceptions.HTTPError: 404 Client Error: Not Found for url: https://api.wandb.ai/graphql

During handling of the above exception, another exception occurred:

Traceback (most recent call last):
  File "/home/bhanu/cuffless_bp/diffusion/lib64/python3.8/site-packages/wandb/sdk/internal/sender.py", line 974, in send_run
    self._init_run(run, config_value_dict)
  File "/home/bhanu/cuffless_bp/diffusion/lib64/python3.8/site-packages/wandb/sdk/internal/sender.py", line 1012, in _init_run
    server_run, inserted, server_messages = self._api.upsert_run(
  File "/home/bhanu/cuffless_bp/diffusion/lib64/python3.8/site-packages/wandb/apis/normalize.py", line 73, in wrapper
    raise err
  File "/home/bhanu/cuffless_bp/diffusion/lib64/python3.8/site-packages/wandb/apis/normalize.py", line 41, in wrapper
    return func(*args, **kwargs)
  File "/home/bhanu/cuffless_bp/diffusion/lib64/python3.8/site-packages/wandb/sdk/internal/internal_api.py", line 1999, in upsert_run
    response = self.gql(
  File "/home/bhanu/cuffless_bp/diffusion/lib64/python3.8/site-packages/wandb/sdk/internal/internal_api.py", line 330, in gql
    ret = self._retry_gql(
  File "/home/bhanu/cuffless_bp/diffusion/lib64/python3.8/site-packages/wandb/sdk/lib/retry.py", line 147, in __call__
    retry_timedelta_triggered = check_retry_fn(e)
  File "/home/bhanu/cuffless_bp/diffusion/lib64/python3.8/site-packages/wandb/util.py", line 964, in check_retry_fn
    return fallback_retry_fn(e)
  File "/home/bhanu/cuffless_bp/diffusion/lib64/python3.8/site-packages/wandb/util.py", line 906, in no_retry_auth
    raise CommError(
wandb.errors.CommError: It appears that you do not have permission to access the requested resource. Please reach out to the project owner to grant you access. If you have the correct permissions, verify that there are no issues with your networking setup.(Error 404: Not Found)
2025-03-24 15:12:20,168 DEBUG   HandlerThread:2523557 [handler.py:handle_request():144] handle_request: shutdown
2025-03-24 15:12:20,168 INFO    HandlerThread:2523557 [handler.py:finish():840] shutting down handler
2025-03-24 15:12:20,238 INFO    WriterThread:2523557 [datastore.py:close():294] close: /scratch/bhanu/cuffless_bp/Cuffless_BP_Estimation_Diffusion_Model/wandb/run-20250324_151219-INSERT ID HERE/run-INSERT ID HERE.wandb
2025-03-24 15:12:20,842 INFO    SenderThread:2523557 [sender.py:finish():1531] shutting down sender
